Workbook

Sheet TOP客户累计改善清单
B2: 1.表格列宽不能超过2个中文字节或者4个英文字节（最多不能超3中文字节或6英文字节，序号只能1中文字节2个英文字节内）； 2.列宽超过的，获得大象眼睛奖并做检讨，且和晋级/晋升/敬业度考核等绑定。
B3: 发运超时商家维度-TOP客户改善名单累计表
B4: 数据来源:T-1全链路管家报表-抖音/淘天→发货-揽收超时/揽收-发运超时→客户层； 商家端结合虚假轨迹管控要求 ：近7天上榜次数超3次，关闭商家“揽收兜底”使用权限。
B5: 3 | C5: 3 | D5: 3 | E5: 8 | F5: 10 | G5: 6 | H5: 2 | J5: 2 | K5: 2 | L5: 3 | M5: 3 | N5: 3 | O5: 3 | P5: 3 | Q5: 3 | R5: 3 | S5: 3 | T5: 8 | U5: 8 | V5: 3 | W5: 2
B6: 上榜日期 | C6: 省 | D6: 分部名称 | E6: 唯一值（分部名称+客户名称+客户编码 | F6: 客户名称 | G6: 客户编码 | H6: 是否配置发运兜底 | I6: 一级积分清退次数 | J6: 平台 | K6: 上榜次数 | L6: 揽收-发运超时 | T6: 超时原因 | U6: 整改动作 | V6: 达成日期 | W6: 是否达成
L7: 抖音平台 | P7: 淘天平台
L8: 超24h | M8: 超36h | O8: 超48h | P8: 超24h | Q8: 超36h | S8: 超48h
L9: 票件量 | M9: 单量 | N9: 超时率 | O9: 票件量 | P9: 票件量 | Q9: 单量 | R9: 超时率 | S9: 票件量
B10: 46092 | C10: 杭州 | D10: 浙江杭州萧山区新塘公司 | E10: 浙江杭州萧山区新塘公司红宝石分部-沐洛311420786786 | F10: 红宝石分部-沐洛 | G10: 311420786786 | H10: 今日已关闭揽收兜底 | I10: =_xlfn.IFNA(_xlfn.XLOOKUP(_xlfn.XLOOKUP(D10,上榜过且清退过的网点!H:H,上榜过且清退过的网点!I:I),上榜过且清退过的网点!A:A,上榜过且清退过的网点!D:D),0) -> 0 | J10: 淘天 | K10: 7 | L10: 0 | M10: 0 | N10: 0 | O10: 0 | P10: 2229 | Q10: 1711 | R10: 18.48% | S10: 806 | T10: 客户缺货 | U10: 72H交不出做退回 | V10: - | W10: -
B11: 46092 | C11: 苏州 | D11: 江苏南通海门国际家纺城公司天补分部 | E11: 江苏南通海门国际家纺城公司天补分部888279华诺(唯客)102342100146 | F11: 888279华诺(唯客) | G11: 102342100146 | I11: =_xlfn.IFNA(_xlfn.XLOOKUP(_xlfn.XLOOKUP(D11,上榜过且清退过的网点!H:H,上榜过且清退过的网点!I:I),上榜过且清退过的网点!A:A,上榜过且清退过的网点!D:D),0) -> 0 | J11: 淘天 | K11: 1 | L11: 2 | M11: 1 | N11: 0.25% | O11: 1 | P11: 2722 | Q11: 1589 | R11: 32.15% | S11: 29 | T11: 客户缺货 | U11: 超36小时的订单做始发退回 | V11: 46096 | W11: -
B12: 46092 | C12: 广佛中 | D12: 广东广州从化区公司汽博服务部 | E12: 广东广州从化区公司汽博服务部维特丝洗护旗舰店迪仕曼旗舰店-小红书京东淘宝-钟落潭维特丝102358210069 | F12: 维特丝洗护旗舰店迪仕曼旗舰店-小红书京东淘宝-钟落潭维特丝 | G12: 102358210069 | I12: =_xlfn.IFNA(_xlfn.XLOOKUP(_xlfn.XLOOKUP(D12,上榜过且清退过的网点!H:H,上榜过且清退过的网点!I:I),上榜过且清退过的网点!A:A,上榜过且清退过的网点!D:D),0) -> 0 | J12: 淘天 | K12: 1 | L12: 0 | M12: 0 | N12: 0 | O12: 0 | P12: 1781 | Q12: 1086 | R12: 3.6% | S12: 352 | T12: 客户缺货 | U12: - | V12: 46096 | W12: -
B13: 46092 | C13: 义乌 | D13: 浙江义乌稠江汇通路公司物流园服务部 | E13: 浙江义乌稠江汇通路公司物流园服务部菜鸟仓c2m----tb62883211322003 | F13: 菜鸟仓c2m----tb6288 | G13: 3211322003 | I13: =_xlfn.IFNA(_xlfn.XLOOKUP(_xlfn.XLOOKUP(D13,上榜过且清退过的网点!H:H,上榜过且清退过的网点!I:I),上榜过且清退过的网点!A:A,上榜过且清退过的网点!D:D),0) -> 0 | J13: 淘天 | K13: 2 | L13: 0 | M13: 0 | N13: 0 | O13: 0 | P13: 1348 | Q13: 1008 | R13: 0.86% | S13: 475 | T13: 商家打包不出来 | U13: 超36小时的订单做始发退回 | V13: 46096 | W13: -
B14: 46092 | C14: 南京 | D14: 江苏南京浦口区新城公司 | E14: 江苏南京浦口区新城公司凤凰新华书店211149548426 | F14: 凤凰新华书店 | G14: 211149548426 | H14: 今日已关闭揽收兜底 | I14: =_xlfn.IFNA(_xlfn.XLOOKUP(_xlfn.XLOOKUP(D14,上榜过且清退过的网点!H:H,上榜过且清退过的网点!I:I),上榜过且清退过的网点!A:A,上榜过且清退过的网点!D:D),0) -> 0 | J14: 淘天 | K14: 4 | L14: 5 | M14: 4 | N14: 0.84% | O14: 4 | P14: 915 | Q14: 846 | R14: 2.53% | S14: 494 | T14: 国营企业，9点之后一直在揽收又交不到分拨中心，考核一直有但是网点没改善 | U14: 省总对接拉群采取措施解决 | V14: - | W14: -
B15: 46092 | C15: 海南 | D15: 海南东方市公司 | E15: 海南东方市公司执vKS570342662455 | F15: 执vKS | G15: 570342662455 | I15: =_xlfn.IFNA(_xlfn.XLOOKUP(_xlfn.XLOOKUP(D15,上榜过且清退过的网点!H:H,上榜过且清退过的网点!I:I),上榜过且清退过的网点!A:A,上榜过且清退过的网点!D:D),0) -> 0 | J15: 抖音 | K15: 1 | L15: 3819 | M15: 2245 | N15: 39.12% | O15: 2160 | P15: 0 | Q15: 0 | R15: 0 | S15: 0 | T15: 客户缺货 | U15: 已关闭批里揽收，目前是手动揽收，已告知超时之前做始发退回，不允许超时 | V15: 46094 | W15: -
B16: 46092 | C16: 河南 | D16: 河南鹿邑县公司涡北镇物流园分部 | E16: 河南鹿邑县公司涡北镇物流园分部管阳仓25279351394 | F16: 管阳仓2 | G16: 5279351394 | I16: =_xlfn.IFNA(_xlfn.XLOOKUP(_xlfn.XLOOKUP(D16,上榜过且清退过的网点!H:H,上榜过且清退过的网点!I:I),上榜过且清退过的网点!A:A,上榜过且清退过的网点!D:D),0) -> 1 | J16: 抖音 | K16: 1 | L16: 1990 | M16: 1908 | N16: 17.89% | O16: 30 | P16: 28 | Q16: 26 | R16: 18.18% | S16: 1 | T16: 缺货客户，发花茶,日均两万单且交货太晚,导致跟不上车 | U16: 今天不再给客户充值单号,以免形成恶性循环。旧单全部清完再发货。 | V16: 46095 | W16: -
B17: 46092 | C17: 揭阳 | D17: 广东汕头潮南新两英公司 | E17: 广东汕头潮南新两英公司予棉内衣-KH-燕雯678825346921 | F17: 予棉内衣-KH-燕雯 | G17: 678825346921 | I17: =_xlfn.IFNA(_xlfn.XLOOKUP(_xlfn.XLOOKUP(D17,上榜过且清退过的网点!H:H,上榜过且清退过的网点!I:I),上榜过且清退过的网点!A:A,上榜过且清退过的网点!D:D),0) -> 0 | J17: 抖音 | K17: 1 | L17: 1987 | M17: 1822 | N17: 56.99% | O17: 209 | P17: 0 | Q17: 0 | R17: 0 | S17: 0 | T17: 商家缺货 | U17: 已通知厂家增加人手生产 | V17: 46097 | W17: -
B18: 46092 | C18: 湖北 | D18: 湖北潜江公司艾草分部 | E18: 湖北潜江公司艾草分部刘俊-梵悦VanJoy446790202501 | F18: 刘俊-梵悦VanJoy | G18: 446790202501 | I18: =_xlfn.IFNA(_xlfn.XLOOKUP(_xlfn.XLOOKUP(D18,上榜过且清退过的网点!H:H,上榜过且清退过的网点!I:I),上榜过且清退过的网点!A:A,上榜过且清退过的网点!D:D),0) -> 1 | J18: 抖音 | K18: 1 | L18: 1736 | M18: 1608 | N18: 73.63% | O18: 0 | P18: 0 | Q18: 0 | R18: 0 | S18: 0 | T18: 商家缺货 | U18: 催促客户及时给货 | V18: 46096 | W18: -
B19: 46092 | C19: 广佛中 | D19: 广东广州花都区新雅公司利佳分部 | E19: 广东广州花都区新雅公司利佳分部P93-穆辛女装-抖音-赵总678459100181 | F19: P93-穆辛女装-抖音-赵总 | G19: 678459100181 | I19: =_xlfn.IFNA(_xlfn.XLOOKUP(_xlfn.XLOOKUP(D19,上榜过且清退过的网点!H:H,上榜过且清退过的网点!I:I),上榜过且清退过的网点!A:A,上榜过且清退过的网点!D:D),0) -> 2 | J19: 抖音 | K19: 2 | L19: 1412 | M19: 1277 | N19: - | O19: 834 | P19: 0 | Q19: 0 | R19: 0 | S19: 0 | T19: 服装客户，日均2万票，缺货 | U19: 客户同意做始发退回换单发，网点现在做超36H交件的 | V19: 46096 | W19: -
B20: 46093 | C20: 揭阳 | D20: 广东汕头潮南新两英公司 | E20: 广东汕头潮南新两英公司予棉内衣-KH-燕雯678825346921 | F20: 予棉内衣-KH-燕雯 | G20: 678825346921 | I20: =_xlfn.IFNA(_xlfn.XLOOKUP(_xlfn.XLOOKUP(D20,上榜过且清退过的网点!H:H,上榜过且清退过的网点!I:I),上榜过且清退过的网点!A:A,上榜过且清退过的网点!D:D),0) -> 0 | J20: 抖音 | K20: 2 | L20: 4145 | M20: 4037 | N20: 59.53% | O20: 68 | P20: 0 | Q20: 0 | R20: 0 | S20: 0 | T20: 商家缺货 | U20: 已通知厂家增加人手生产 | V20: 46097 | W20: -
B21: 46093 | C21: 深莞惠 | D21: 广东东莞新企石公司 | E21: 广东东莞新企石公司张小军588063778008 | F21: 张小军 | G21: 588063778008 | I21: =_xlfn.IFNA(_xlfn.XLOOKUP(_xlfn.XLOOKUP(D21,上榜过且清退过的网点!H:H,上榜过且清退过的网点!I:I),上榜过且清退过的网点!A:A,上榜过且清退过的网点!D:D),0) -> 0 | J21: 抖音 | K21: 1 | L21: 3070 | M21: 2812 | N21: 35.16% | O21: 20 | P21: 5 | Q21: 2 | R21: 22.22% | S21: 2 | T21: 客户发件延误 | U21: 省区拉群对接督促客户12h内交件 | V21: 46096 | W21: -
B22: 46093 | C22: 海南 | D22: 海南东方市公司 | E22: 海南东方市公司执vKS570342662455 | F22: 执vKS | G22: 570342662455 | I22: =_xlfn.IFNA(_xlfn.XLOOKUP(_xlfn.XLOOKUP(D22,上榜过且清退过的网点!H:H,上榜过且清退过的网点!I:I),上榜过且清退过的网点!A:A,上榜过且清退过的网点!D:D),0) -> 0 | J22: 抖音 | K22: 2 | L22: 2244 | M22: 2035 | N22: 75.48% | O22: 2035 | P22: 0 | Q22: 0 | R22: 0 | S22: 0 | T22: 客户缺货 | U22: 已关闭批里揽收，目前是手动揽收，已告知超时之前做始发退回，不允许超时 | V22: 46094 | W22: -
B23: 46093 | C23: 苏州 | D23: 江苏苏州常熟市招商城公司华联服务部 | E23: 江苏苏州常熟市招商城公司华联服务部聚福-蓝续服饰484398576648 | F23: 聚福-蓝续服饰 | G23: 484398576648 | H23: 是 | I23: =_xlfn.IFNA(_xlfn.XLOOKUP(_xlfn.XLOOKUP(D23,上榜过且清退过的网点!H:H,上榜过且清退过的网点!I:I),上榜过且清退过的网点!A:A,上榜过且清退过的网点!D:D),0) -> 0 | J23: 抖音 | K23: 1 | L23: 2283 | M23: 1656 | N23: 6.18% | O23: 183 | P23: 6 | Q23: 6 | R23: 6.52% | S23: 3 | T23: 商家突然爆单，工厂供货不及时导致的 | U23: 已经督促这两天陆续都会发掉 | V23: 46096 | W23: -
B24: 46093 | C24: 湖北 | D24: 湖北潜江公司艾草分部 | E24: 湖北潜江公司艾草分部刘俊-梵悦VanJoy446790202501 | F24: 刘俊-梵悦VanJoy | G24: 446790202501 | H24: 是 | I24: =_xlfn.IFNA(_xlfn.XLOOKUP(_xlfn.XLOOKUP(D24,上榜过且清退过的网点!H:H,上榜过且清退过的网点!I:I),上榜过且清退过的网点!A:A,上榜过且清退过的网点!D:D),0) -> 1 | J24: 抖音 | K24: 2 | L24: 1487 | M24: 1464 | N24: 58.84% | O24: 617 | P24: 0 | Q24: 0 | R24: 0 | S24: 0 | T24: 商家缺货 | U24: 催促客户及时给货 | V24: 46096 | W24: -
B25: 46093 | C25: 贵州 | D25: 贵州习水县公司 | E25: 贵州习水县公司周陆军5646004933 | F25: 周陆军 | G25: 5646004933 | I25: =_xlfn.IFNA(_xlfn.XLOOKUP(_xlfn.XLOOKUP(D25,上榜过且清退过的网点!H:H,上榜过且清退过的网点!I:I),上榜过且清退过的网点!A:A,上榜过且清退过的网点!D:D),0) -> 0 | J25: 淘天 | K25: 3 | L25: 0 | M25: 0 | N25: 0 | O25: 0 | P25: 4780 | Q25: 4780 | R25: 100% | S25: 0 | T25: 打单后商家货源不够 | U25: 通知商家改善，按时交件发出 | V25: 46096 | W25: -
B26: 46093 | C26: 杭州 | D26: 浙江杭州萧山区新塘公司 | E26: 浙江杭州萧山区新塘公司红宝石分部-沐洛311420786786 | F26: 红宝石分部-沐洛 | G26: 311420786786 | H26: 是 | I26: =_xlfn.IFNA(_xlfn.XLOOKUP(_xlfn.XLOOKUP(D26,上榜过且清退过的网点!H:H,上榜过且清退过的网点!I:I),上榜过且清退过的网点!A:A,上榜过且清退过的网点!D:D),0) -> 0 | J26: 淘天 | K26: 7 | L26: 0 | M26: 0 | N26: 0 | O26: 0 | P26: 2366 | Q26: 1795 | R26: 20.53% | S26: 911 | T26: 客户缺货 | U26: 72H交不出做退回 | V26: - | W26: -
B27: 46093 | C27: 南京 | D27: 江苏南京浦口区新城公司 | E27: 江苏南京浦口区新城公司凤凰新华书店211149548426 | F27: 凤凰新华书店 | G27: 211149548426 | H27: 是 | I27: =_xlfn.IFNA(_xlfn.XLOOKUP(_xlfn.XLOOKUP(D27,上榜过且清退过的网点!H:H,上榜过且清退过的网点!I:I),上榜过且清退过的网点!A:A,上榜过且清退过的网点!D:D),0) -> 0 | J27: 淘天 | K27: 5 | L27: 3 | M27: 2 | N27: 0.41% | O27: 2 | P27: 1717 | Q27: 1614 | R27: 5.57% | S27: 1553 | T27: 国营企业，9点之后一直在揽收又交不到分拨中心，考核一直有但是网点没改善 | U27: 省总对接拉群采取措施解决 | V27: - | W27: -
B28: 46093 | C28: 湖北 | D28: 湖北营销市场部 | E28: 湖北营销市场部好礼云仓392472329696 | F28: 好礼云仓 | G28: 392472329696 | H28: 是 | I28: =_xlfn.IFNA(_xlfn.XLOOKUP(_xlfn.XLOOKUP(D28,上榜过且清退过的网点!H:H,上榜过且清退过的网点!I:I),上榜过且清退过的网点!A:A,上榜过且清退过的网点!D:D),0) -> 0 | J28: 淘天 | K28: 1 | L28: 0 | M28: 0 | N28: 0 | O28: 0 | P28: 3087 | Q28: 652 | R28: 5.09% | S28: 106 | T28: 分拨滞留 | U28: 已解决 | V28: 46094 | W28: -
B29: 46093 | C29: 贵州 | D29: 贵州贵阳南明青年路公司 | E29: 贵州贵阳南明青年路公司刘少云551614677629 | F29: 刘少云 | G29: 551614677629 | I29: =_xlfn.IFNA(_xlfn.XLOOKUP(_xlfn.XLOOKUP(D29,上榜过且清退过的网点!H:H,上榜过且清退过的网点!I:I),上榜过且清退过的网点!A:A,上榜过且清退过的网点!D:D),0) -> 0 | J29: 淘天 | K29: 1 | L29: 0 | M29: 0 | N29: 0 | O29: 0 | P29: 640 | Q29: 640 | R29: 100% | S29: 0 | T29: 打单后商家货源不够 | U29: 通知商家改善，按时交件发出 | V29: 46096 | W29: -
B30: 46094 | C30: 广佛中 | D30: 广东广州增城新塘白江村公司东洲服务部 | E30: 广东广州增城新塘白江村公司东洲服务部100812慕至尚服饰-李威客户459740100812 | F30: 100812慕至尚服饰-李威客户 | G30: 459740100812 | H30: 是 | I30: =_xlfn.IFNA(_xlfn.XLOOKUP(_xlfn.XLOOKUP(D30,上榜过且清退过的网点!H:H,上榜过且清退过的网点!I:I),上榜过且清退过的网点!A:A,上榜过且清退过的网点!D:D),0) -> 0 | J30: 抖音 | K30: 1 | L30: 3347 | M30: 2645 | N30: 23.5% | O30: 1820 | P30: 0 | Q30: 0 | R30: 0 | S30: 0 | T30: 服装客户缺货 | U30: 后续超时部分及时通 知客户换单,避免影响时效 | V30: 46095 | W30: -
B31: 46094 | C31: 义乌 | D31: 浙江义乌稠江汇通路公司极电分部 | E31: 浙江义乌稠江汇通路公司极电分部JD5-T极电云仓五淘-J极电云仓五楼京-P极电云仓五拼-D极电云仓五楼抖-K极电云仓五楼快-X极电云仓5红622998221099 | F31: JD5-T极电云仓五淘-J极电云仓五楼京-P极电云仓五拼-D极电云仓五楼抖-K极电云仓五楼快-X极电云仓5红 | G31: 622998221099 | I31: =_xlfn.IFNA(_xlfn.XLOOKUP(_xlfn.XLOOKUP(D31,上榜过且清退过的网点!H:H,上榜过且清退过的网点!I:I),上榜过且清退过的网点!A:A,上榜过且清退过的网点!D:D),0) -> 1 | J31: 抖音 | K31: 1 | L31: 2403 | M31: 2400 | N31: 10.88% | O31: 2389 | P31: 7 | Q31: 5 | R31: 0.18% | S31: 5 | T31: 联系省区网管,未得到回复 | V31: - | W31: -
B32: 46094 | C32: 广西 | D32: 广西南宁青秀区凤岭公司崇铭服务部 | E32: 广西南宁青秀区凤岭公司崇铭服务部10013拼多多果幽生鲜甄选抖音三亩地农业甄选31305910013 | F32: 10013拼多多果幽生鲜甄选抖音三亩地农业甄选 | G32: 31305910013 | I32: =_xlfn.IFNA(_xlfn.XLOOKUP(_xlfn.XLOOKUP(D32,上榜过且清退过的网点!H:H,上榜过且清退过的网点!I:I),上榜过且清退过的网点!A:A,上榜过且清退过的网点!D:D),0) -> 0 | J32: 抖音 | K32: 1 | L32: 2250 | M32: 1914 | N32: 14.78% | O32: 1894 | P32: 0 | Q32: 0 | R32: 0 | S32: 0 | T32: 客户缺货,打包又 晚,导致当晚没有交件 | U32: 已安排人员协助打 包,后续会注意时效 | V32: 46096 | W32: -
B33: 46094 | C33: 湖北 | D33: 湖北潜江公司艾草分部 | E33: 湖北潜江公司艾草分部刘俊-梵悦VanJoy446790202501 | F33: 刘俊-梵悦VanJoy | G33: 446790202501 | H33: 是 | I33: =_xlfn.IFNA(_xlfn.XLOOKUP(_xlfn.XLOOKUP(D33,上榜过且清退过的网点!H:H,上榜过且清退过的网点!I:I),上榜过且清退过的网点!A:A,上榜过且清退过的网点!D:D),0) -> 1 | J33: 抖音 | K33: 3 | L33: 2026 | M33: 1902 | N33: 43.92% | O33: 0 | P33: 0 | Q33: 0 | R33: 0 | S33: 0 | T33: 商家缺货 | U33: 催促客户及时给货 | V33: 46096 | W33: -
B34: 46094 | C34: 海南 | D34: 海南东方市公司 | E34: 海南东方市公司执vKS570342662455 | F34: 执vKS | G34: 570342662455 | I34: =_xlfn.IFNA(_xlfn.XLOOKUP(_xlfn.XLOOKUP(D34,上榜过且清退过的网点!H:H,上榜过且清退过的网点!I:I),上榜过且清退过的网点!A:A,上榜过且清退过的网点!D:D),0) -> 0 | J34: 抖音 | K34: 3 | L34: 3273 | M34: 1624 | N34: 40.65% | O34: 1622 | P34: 0 | Q34: 0 | R34: 0 | S34: 0 | T34: 客户缺货 | U34: 已关闭批里揽收，目前是手动揽收，已告知超时之前做始发退回，不允许超时 | V34: 46094 | W34: -
B35: 46094 | C35: 贵州 | D35: 贵州遵义新仁怀市公司苍龙街道服务部 | E35: 贵州遵义新仁怀市公司苍龙街道服务部钰洁小卖部983759102326 | F35: 钰洁小卖部 | G35: 983759102326 | I35: =_xlfn.IFNA(_xlfn.XLOOKUP(_xlfn.XLOOKUP(D35,上榜过且清退过的网点!H:H,上榜过且清退过的网点!I:I),上榜过且清退过的网点!A:A,上榜过且清退过的网点!D:D),0) -> 0 | J35: 淘天 | K35: 1 | L35: 0 | M35: 0 | N35: 0 | O35: 0 | P35: 2800 | Q35: 2800 | R35: 50% | S35: 2800 | T35: 商家缺货 | U35: 通知商家改善，按时交件发出 | V35: 46096 | W35: -
B36: 46094 | C36: 贵州 | D36: 贵州贵阳观山湖世纪城公司 | E36: 贵州贵阳观山湖世纪城公司王孟利551515111111 | F36: 王孟利 | G36: 551515111111 | I36: =_xlfn.IFNA(_xlfn.XLOOKUP(_xlfn.XLOOKUP(D36,上榜过且清退过的网点!H:H,上榜过且清退过的网点!I:I),上榜过且清退过的网点!A:A,上榜过且清退过的网点!D:D),0) -> 0 | J36: 淘天 | K36: 2 | L36: 0 | M36: 0 | N36: 0 | O36: 0 | P36: 2088 | Q36: 2013 | R36: 96.36% | S36: 113 | T36: 商家缺货 | U36: 通知商家改善，按时交件发出 | V36: 46096 | W36: -
B37: 46094 | C37: 杭州 | D37: 浙江杭州萧山区新塘公司 | E37: 浙江杭州萧山区新塘公司红宝石分部-沐洛311420786786 | F37: 红宝石分部-沐洛 | G37: 311420786786 | H37: 是 | I37: =_xlfn.IFNA(_xlfn.XLOOKUP(_xlfn.XLOOKUP(D37,上榜过且清退过的网点!H:H,上榜过且清退过的网点!I:I),上榜过且清退过的网点!A:A,上榜过且清退过的网点!D:D),0) -> 0 | J37: 淘天 | K37: 7 | L37: 0 | M37: 0 | N37: 0 | O37: 0 | P37: 2158 | Q37: 1423 | R37: 15.14% | S37: 647 | T37: 客户缺货 | U37: 72H交不出做退回 | V37: - | W37: -
B38: 46094 | C38: 南京 | D38: 江苏南京浦口区新城公司 | E38: 江苏南京浦口区新城公司凤凰新华书店211149548426 | F38: 凤凰新华书店 | G38: 211149548426 | H38: 是 | I38: =_xlfn.IFNA(_xlfn.XLOOKUP(_xlfn.XLOOKUP(D38,上榜过且清退过的网点!H:H,上榜过且清退过的网点!I:I),上榜过且清退过的网点!A:A,上榜过且清退过的网点!D:D),0) -> 0 | J38: 淘天 | K38: 5 | L38: 4 | M38: 0 | N38: 0% | O38: 0 | P38: 1632 | Q38: 1149 | R38: 3.61% | S38: 881 | T38: 国营企业，9点之后一直在揽收又交不到分拨中心，考核一直有但是网点没改善 | U38: 省总对接拉群采取措施解决 | V38: - | W38: -
B39: 46094 | C39: 义乌 | D39: 浙江义乌稠江弘贸路公司 | E39: 浙江义乌稠江弘贸路公司美优baihuo355310100001 | F39: 美优baihuo | G39: 355310100001 | H39: 是 | I39: =_xlfn.IFNA(_xlfn.XLOOKUP(_xlfn.XLOOKUP(D39,上榜过且清退过的网点!H:H,上榜过且清退过的网点!I:I),上榜过且清退过的网点!A:A,上榜过且清退过的网点!D:D),0) -> 0 | J39: 淘天 | K39: 1 | L39: 0 | M39: 0 | N39: 0 | O39: 0 | P39: 1185 | Q39: 803 | R39: 0.59% | S39: 194 | T39: 联系省区网管,未得到回复 | V39: - | W39: -
B40: 46095 | C40: 北京 | D40: 河北韵达鑫通公司慕菲兰分部 | E40: 河北韵达鑫通公司慕菲兰分部妮雅依人服饰-张雷524818149441 | F40: 妮雅依人服饰-张雷 | G40: 524818149441 | I40: =_xlfn.IFNA(_xlfn.XLOOKUP(_xlfn.XLOOKUP(D40,上榜过且清退过的网点!H:H,上榜过且清退过的网点!I:I),上榜过且清退过的网点!A:A,上榜过且清退过的网点!D:D),0) -> 3 | J40: 抖音 | K40: 2 | L40: 4791 | M40: 4405 | N40: 25.62% | O40: 12 | P40: 0 | Q40: 0 | R40: 0 | S40: 0 | T40: 客户缺货,打包延迟,导致未及时交件 | U40: 已加班及时处理打包发出且做始发退回 | V40: 46096 | W40: -
B41: 46095 | C41: 广西 | D41: 广西南宁青秀区凤岭公司崇铭服务部 | E41: 广西南宁青秀区凤岭公司崇铭服务部芒果19淘宝cxxxxxxt京东Qq417092644拼多多曾似水果生鲜官方旗舰店抖音农夫果园甄选快手阿超在果园白马视频号蓓蕾家的日常生活3130596019 | F41: 芒果19淘宝cxxxxxxt京东Qq417092644拼多多曾似水果生鲜官方旗舰店抖音农夫果园甄选快手阿超在果园白马视频号蓓蕾家的日常生活 | G41: 3130596019 | H41: 是 | I41: =_xlfn.IFNA(_xlfn.XLOOKUP(_xlfn.XLOOKUP(D41,上榜过且清退过的网点!H:H,上榜过且清退过的网点!I:I),上榜过且清退过的网点!A:A,上榜过且清退过的网点!D:D),0) -> 0 | J41: 抖音 | K41: 1 | L41: 9535 | M41: 3920 | N41: 27.88% | O41: 2765 | P41: 0 | Q41: 0 | R41: 0 | S41: 0 | T41: 生鲜客户，缺货打包晚 | U41: 安排人员协助打 包,后续会注意时效 | V41: 46096 | W41: -
...

Sheet 近7天累计TOP客户
A1: 日期 | B1: 省 | C1: 分部名称 | D1: 唯一值（分部名称+客户名称+客户编码 | E1: 客户名称 | F1: 客户编码 | G1: 揽收-发运超时 | O1: 平台区分
G2: 抖音平台 | K2: 淘天平台
G3: 超24h | H3: 超36h | J3: 超48h | K3: 超24h | L3: 超36h | N3: 超48h
G4: 票件量 | H4: 单量 | I4: 超时率 | J4: 票件量 | K4: 票件量 | L4: 单量 | M4: 超时率 | N4: 票件量
A5: 46221 | B5: 广佛中 | C5: 广东佛山南海新河村公司 | D5: 广东佛山南海新河村公司公司直营-曼馨抖音珠茉美妆-启能拼多多大赚顺-启能菜鸟tb4336332592572014411986 | E5: 公司直营-曼馨抖音珠茉美妆-启能拼多多大赚顺-启能菜鸟tb4336332592 | F5: 572014411986 | G5: 2333 | H5: 1960 | I5: 25.42% | J5: 86 | K5: 0 | L5: 0 | M5: 0 | N5: 0 | O5: 抖音 | P5: =_xlfn.XLOOKUP(D5,TOP客户累计改善清单!E:E,TOP客户累计改善清单!K:K) -> 2 | Q5: =IF(O5="抖音",H5,L5) -> 1960 | R5: =IF(O5="抖音",ROUND(I5*100,2),ROUND(M5*100,2)) -> 25.42 | S5: =C5&"・"&E5&"【"&Q5&"票"&","&R5&"%"&"】"&P5&"次" -> 广东佛山南海新河村公司・公司直营-曼馨抖音珠茉美妆-启能拼多多大赚顺-启能菜鸟tb4336332592【1960票,25.42%】2次
A6: 46221 | B6: 苏州 | C6: 江苏苏州常熟市招商城公司 | D6: 江苏苏州常熟市招商城公司聚福-小灰兔681709798994 | E6: 聚福-小灰兔 | F6: 681709798994 | G6: 5014 | H6: 1845 | I6: 3.99% | J6: 12 | K6: 0 | L6: 0 | M6: 0 | N6: 0 | O6: 抖音 | P6: =_xlfn.XLOOKUP(D6,TOP客户累计改善清单!E:E,TOP客户累计改善清单!K:K) -> 1 | Q6: =IF(O6="抖音",H6,L6) -> 1845 | R6: =IF(O6="抖音",ROUND(I6*100,2),ROUND(M6*100,2)) -> 3.99 | S6: =C6&"・"&E6&"【"&Q6&"票"&","&R6&"%"&"】"&P6&"次" -> 江苏苏州常熟市招商城公司・聚福-小灰兔【1845票,3.99%】1次
A7: 46221 | B7: 河北 | C7: 河北南宫市公司 | D7: 河北南宫市公司胜利大街惠-岳世辉-快手追风潮童-抖音光伟童装工厂店-拼多多左左右右童-视频号小可爱童装-淘宝贵泽童装工厂951800650006 | E7: 胜利大街惠-岳世辉-快手追风潮童-抖音光伟童装工厂店-拼多多左左右右童-视频号小可爱童装-淘宝贵泽童装工厂 | F7: 951800650006 | G7: 1990 | H7: 1585 | I7: 26.84% | J7: 193 | K7: 0 | L7: 0 | M7: 0 | N7: 0 | O7: 抖音 | P7: =_xlfn.XLOOKUP(D7,TOP客户累计改善清单!E:E,TOP客户累计改善清单!K:K) -> 2 | Q7: =IF(O7="抖音",H7,L7) -> 1585 | R7: =IF(O7="抖音",ROUND(I7*100,2),ROUND(M7*100,2)) -> 26.84 | S7: =C7&"・"&E7&"【"&Q7&"票"&","&R7&"%"&"】"&P7&"次" -> 河北南宫市公司・胜利大街惠-岳世辉-快手追风潮童-抖音光伟童装工厂店-拼多多左左右右童-视频号小可爱童装-淘宝贵泽童装工厂【1585票,26.84%】2次
A8: 46221 | B8: 深莞惠 | C8: 广东深圳KH公司孟洁分部 | D8: 广东深圳KH公司孟洁分部溪南园829902455147 | E8: 溪南园 | F8: 829902455147 | G8: 2524 | H8: 1335 | I8: 10.48% | J8: 600 | K8: 0 | L8: 0 | M8: 0 | N8: 0 | O8: 抖音 | P8: =_xlfn.XLOOKUP(D8,TOP客户累计改善清单!E:E,TOP客户累计改善清单!K:K) -> 1 | Q8: =IF(O8="抖音",H8,L8) -> 1335 | R8: =IF(O8="抖音",ROUND(I8*100,2),ROUND(M8*100,2)) -> 10.48 | S8: =C8&"・"&E8&"【"&Q8&"票"&","&R8&"%"&"】"&P8&"次" -> 广东深圳KH公司孟洁分部・溪南园【1335票,10.48%】1次
A9: 46221 | B9: 安徽 | C9: 安徽亳州谯城道东公司 | D9: 安徽亳州谯城道东公司卢宏杰云仓T袅店K袅烟阁P燃叫冲饮旗舰店S袅烟阁慈行D燃叫咖啡582367513148 | E9: 卢宏杰云仓T袅店K袅烟阁P燃叫冲饮旗舰店S袅烟阁慈行D燃叫咖啡 | F9: 582367513148 | G9: 2141 | H9: 1228 | I9: 32.36% | J9: 3 | K9: 0 | L9: 0 | M9: 0 | N9: 0 | O9: 抖音 | P9: =_xlfn.XLOOKUP(D9,TOP客户累计改善清单!E:E,TOP客户累计改善清单!K:K) -> 1 | Q9: =IF(O9="抖音",H9,L9) -> 1228 | R9: =IF(O9="抖音",ROUND(I9*100,2),ROUND(M9*100,2)) -> 32.36 | S9: =C9&"・"&E9&"【"&Q9&"票"&","&R9&"%"&"】"&P9&"次" -> 安徽亳州谯城道东公司・卢宏杰云仓T袅店K袅烟阁P燃叫冲饮旗舰店S袅烟阁慈行D燃叫咖啡【1228票,32.36%】1次
A10: 46221 | B10: 深莞惠 | C10: 广东深圳公司锌东经KH分部 | D10: 广东深圳公司锌东经KH分部李圳-菜鸟-驰界贸易518066666666 | E10: 李圳-菜鸟-驰界贸易 | F10: 518066666666 | G10: 0 | H10: 0 | I10: 0 | J10: 0 | K10: 995 | L10: 822 | M10: 18.75% | N10: 0 | O10: 淘天 | P10: =_xlfn.XLOOKUP(D10,TOP客户累计改善清单!E:E,TOP客户累计改善清单!K:K) -> 1 | Q10: =IF(O10="抖音",H10,L10) -> 822 | R10: =IF(O10="抖音",ROUND(I10*100,2),ROUND(M10*100,2)) -> 18.75 | S10: =C10&"・"&E10&"【"&Q10&"票"&","&R10&"%"&"】"&P10&"次" -> 广东深圳公司锌东经KH分部・李圳-菜鸟-驰界贸易【822票,18.75%】1次
A11: 46221 | B11: 湖北 | C11: 湖北营销市场部 | D11: 湖北营销市场部好礼云仓392472329696 | E11: 好礼云仓 | F11: 392472329696 | G11: 0 | H11: 0 | I11: 0 | J11: 0 | K11: 1564 | L11: 521 | M11: 4.48% | N11: 8 | O11: 淘天 | P11: =_xlfn.XLOOKUP(D11,TOP客户累计改善清单!E:E,TOP客户累计改善清单!K:K) -> 1 | Q11: =IF(O11="抖音",H11,L11) -> 521 | R11: =IF(O11="抖音",ROUND(I11*100,2),ROUND(M11*100,2)) -> 4.48 | S11: =C11&"・"&E11&"【"&Q11&"票"&","&R11&"%"&"】"&P11&"次" -> 湖北营销市场部・好礼云仓【521票,4.48%】1次
A12: 46221 | B12: 安徽 | C12: 安徽合肥凤麟路公司 | D12: 安徽合肥凤麟路公司品越供应链225317100063 | E12: 品越供应链 | F12: 225317100063 | G12: 99 | H12: 44 | I12: 0.14% | J12: 21 | K12: 450 | L12: 423 | M12: 3.44% | N12: 11 | O12: 淘天 | P12: =_xlfn.XLOOKUP(D12,TOP客户累计改善清单!E:E,TOP客户累计改善清单!K:K) -> 1 | Q12: =IF(O12="抖音",H12,L12) -> 423 | R12: =IF(O12="抖音",ROUND(I12*100,2),ROUND(M12*100,2)) -> 3.44 | S12: =C12&"・"&E12&"【"&Q12&"票"&","&R12&"%"&"】"&P12&"次" -> 安徽合肥凤麟路公司・品越供应链【423票,3.44%】1次
A13: 46221 | B13: 义乌 | C13: 浙江温州洞头区瓯江口公司 | D13: 浙江温州洞头区瓯江口公司瑞鸿菜鸟仓3256866238 | E13: 瑞鸿菜鸟仓 | F13: 3256866238 | G13: 0 | H13: 0 | I13: 0 | J13: 0 | K13: 383 | L13: 383 | M13: 37.77% | N13: 0 | O13: 淘天 | P13: =_xlfn.XLOOKUP(D13,TOP客户累计改善清单!E:E,TOP客户累计改善清单!K:K) -> 1 | Q13: =IF(O13="抖音",H13,L13) -> 383 | R13: =IF(O13="抖音",ROUND(I13*100,2),ROUND(M13*100,2)) -> 37.77 | S13: =C13&"・"&E13&"【"&Q13&"票"&","&R13&"%"&"】"&P13&"次" -> 浙江温州洞头区瓯江口公司・瑞鸿菜鸟仓【383票,37.77%】1次
A14: 46221 | B14: 福建 | C14: 福建涵东公司 | D14: 福建涵东公司朱丽萍的C店459974517700 | E14: 朱丽萍的C店 | F14: 459974517700 | G14: 0 | H14: 0 | I14: 0 | J14: 0 | K14: 522 | L14: 383 | M14: 47.7% | N14: 267 | O14: 淘天 | P14: =_xlfn.XLOOKUP(D14,TOP客户累计改善清单!E:E,TOP客户累计改善清单!K:K) -> 1 | Q14: =IF(O14="抖音",H14,L14) -> 383 | R14: =IF(O14="抖音",ROUND(I14*100,2),ROUND(M14*100,2)) -> 47.7 | S14: =C14&"・"&E14&"【"&Q14&"票"&","&R14&"%"&"】"&P14&"次" -> 福建涵东公司・朱丽萍的C店【383票,47.7%】1次
A15: 46222 | B15: 河北 | C15: 河北南宫市公司 | D15: 河北南宫市公司胜利大街惠-岳世辉-快手追风潮童-抖音光伟童装工厂店-拼多多左左右右童-视频号小可爱童装-淘宝贵泽童装工厂951800650006 | E15: 胜利大街惠-岳世辉-快手追风潮童-抖音光伟童装工厂店-拼多多左左右右童-视频号小可爱童装-淘宝贵泽童装工厂 | F15: 951800650006 | G15: 2198 | H15: 1973 | I15: 34.93% | J15: 195 | K15: 0 | L15: 0 | M15: 0 | N15: 0 | O15: 抖音 | P15: =_xlfn.XLOOKUP(D15,TOP客户累计改善清单!E:E,TOP客户累计改善清单!K:K) -> 2 | Q15: =IF(O15="抖音",H15,L15) -> 1973 | R15: =IF(O15="抖音",ROUND(I15*100,2),ROUND(M15*100,2)) -> 34.93 | S15: =C15&"・"&E15&"【"&Q15&"票"&","&R15&"%"&"】"&P15&"次" -> 河北南宫市公司・胜利大街惠-岳世辉-快手追风潮童-抖音光伟童装工厂店-拼多多左左右右童-视频号小可爱童装-淘宝贵泽童装工厂【1973票,34.93%】2次
A16: 46222 | B16: 苏州 | C16: 江苏苏州常熟市招商城公司 | D16: 江苏苏州常熟市招商城公司聚福-小灰兔681709798994 | E16: 聚福-小灰兔 | F16: 681709798994 | G16: 4369 | H16: 1561 | I16: 4.08% | J16: 158 | K16: 0 | L16: 0 | M16: 0 | N16: 0 | O16: 抖音 | P16: =_xlfn.XLOOKUP(D16,TOP客户累计改善清单!E:E,TOP客户累计改善清单!K:K) -> 1 | Q16: =IF(O16="抖音",H16,L16) -> 1561 | R16: =IF(O16="抖音",ROUND(I16*100,2),ROUND(M16*100,2)) -> 4.08 | S16: =C16&"・"&E16&"【"&Q16&"票"&","&R16&"%"&"】"&P16&"次" -> 江苏苏州常熟市招商城公司・聚福-小灰兔【1561票,4.08%】1次
A17: 46222 | B17: 广佛中 | C17: 广东佛山南海新河村公司 | D17: 广东佛山南海新河村公司公司直营-曼馨抖音珠茉美妆-启能拼多多大赚顺-启能菜鸟tb4336332592572014411986 | E17: 公司直营-曼馨抖音珠茉美妆-启能拼多多大赚顺-启能菜鸟tb4336332592 | F17: 572014411986 | G17: 1559 | H17: 1368 | I17: 16.48% | J17: 103 | K17: 0 | L17: 0 | M17: 0 | N17: 0 | O17: 抖音 | P17: =_xlfn.XLOOKUP(D17,TOP客户累计改善清单!E:E,TOP客户累计改善清单!K:K) -> 2 | Q17: =IF(O17="抖音",H17,L17) -> 1368 | R17: =IF(O17="抖音",ROUND(I17*100,2),ROUND(M17*100,2)) -> 16.48 | S17: =C17&"・"&E17&"【"&Q17&"票"&","&R17&"%"&"】"&P17&"次" -> 广东佛山南海新河村公司・公司直营-曼馨抖音珠茉美妆-启能拼多多大赚顺-启能菜鸟tb4336332592【1368票,16.48%】2次
A18: 46222 | B18: 广佛中 | C18: 广东广州增城市新塘公司红石服务部 | D18: 广东广州增城市新塘公司红石服务部Z-巨野H店-YLS服饰工广店D178289113413 | E18: Z-巨野H店-YLS服饰工广店D | F18: 178289113413 | G18: 1308 | H18: 1198 | I18: 37.94% | J18: 94 | K18: 0 | L18: 0 | M18: 0 | N18: 0 | O18: 抖音 | P18: =_xlfn.XLOOKUP(D18,TOP客户累计改善清单!E:E,TOP客户累计改善清单!K:K) -> 1 | Q18: =IF(O18="抖音",H18,L18) -> 1198 | R18: =IF(O18="抖音",ROUND(I18*100,2),ROUND(M18*100,2)) -> 37.94 | S18: =C18&"・"&E18&"【"&Q18&"票"&","&R18&"%"&"】"&P18&"次" -> 广东广州增城市新塘公司红石服务部・Z-巨野H店-YLS服饰工广店D【1198票,37.94%】1次
A19: 46222 | B19: 苏州 | C19: 江苏常熟东南公司 | D19: 江苏常熟东南公司赵振振-郑贵清专属文艺小铺子138213416669 | E19: 赵振振-郑贵清专属文艺小铺子 | F19: 138213416669 | G19: 1996 | H19: 850 | I19: 39.39% | J19: 10 | K19: 0 | L19: 0 | M19: 0 | N19: 0 | O19: 抖音 | P19: =_xlfn.XLOOKUP(D19,TOP客户累计改善清单!E:E,TOP客户累计改善清单!K:K) -> 2 | Q19: =IF(O19="抖音",H19,L19) -> 850 | R19: =IF(O19="抖音",ROUND(I19*100,2),ROUND(M19*100,2)) -> 39.39 | S19: =C19&"・"&E19&"【"&Q19&"票"&","&R19&"%"&"】"&P19&"次" -> 江苏常熟东南公司・赵振振-郑贵清专属文艺小铺子【850票,39.39%】2次
A20: 46222 | B20: 义乌 | C20: 浙江温州洞头区瓯江口公司 | D20: 浙江温州洞头区瓯江口公司瑞鸿菜鸟仓3256866238 | E20: 瑞鸿菜鸟仓 | F20: 3256866238 | G20: 0 | H20: 0 | I20: 0 | J20: 0 | K20: 564 | L20: 559 | M20: 54.17% | N20: 558 | O20: 淘天 | P20: =_xlfn.XLOOKUP(D20,TOP客户累计改善清单!E:E,TOP客户累计改善清单!K:K) -> 1 | Q20: =IF(O20="抖音",H20,L20) -> 559 | R20: =IF(O20="抖音",ROUND(I20*100,2),ROUND(M20*100,2)) -> 54.17 | S20: =C20&"・"&E20&"【"&Q20&"票"&","&R20&"%"&"】"&P20&"次" -> 浙江温州洞头区瓯江口公司・瑞鸿菜鸟仓【559票,54.17%】1次
A21: 46222 | B21: 山西 | C21: 山西长治潞州区公司 | D21: 山西长治潞州区公司佰鹦汇宠物店548280562641 | E21: 佰鹦汇宠物店 | F21: 548280562641 | G21: 442 | H21: 316 | I21: 39.55% | J21: 1 | K21: 544 | L21: 407 | M21: 43.16% | N21: 0 | O21: 淘天 | P21: =_xlfn.XLOOKUP(D21,TOP客户累计改善清单!E:E,TOP客户累计改善清单!K:K) -> 1 | Q21: =IF(O21="抖音",H21,L21) -> 407 | R21: =IF(O21="抖音",ROUND(I21*100,2),ROUND(M21*100,2)) -> 43.16 | S21: =C21&"・"&E21&"【"&Q21&"票"&","&R21&"%"&"】"&P21&"次" -> 山西长治潞州区公司・佰鹦汇宠物店【407票,43.16%】1次
A22: 46222 | B22: 福建 | C22: 福建石狮市公司永红KH分部 | D22: 福建石狮市公司永红KH分部永红-腾-卖灰机的拖鞋362551220010 | E22: 永红-腾-卖灰机的拖鞋 | F22: 362551220010 | G22: 0 | H22: 0 | I22: 0 | J22: 0 | K22: 352 | L22: 352 | M22: 56.41% | N22: 0 | O22: 淘天 | P22: =_xlfn.XLOOKUP(D22,TOP客户累计改善清单!E:E,TOP客户累计改善清单!K:K) -> 1 | Q22: =IF(O22="抖音",H22,L22) -> 352 | R22: =IF(O22="抖音",ROUND(I22*100,2),ROUND(M22*100,2)) -> 56.41 | S22: =C22&"・"&E22&"【"&Q22&"票"&","&R22&"%"&"】"&P22&"次" -> 福建石狮市公司永红KH分部・永红-腾-卖灰机的拖鞋【352票,56.41%】1次
A23: 46222 | B23: 河南 | C23: 河南虞城县公司李老家乡服务站 | D23: 河南虞城县公司李老家乡服务站马开-开0708786651400300 | E23: 马开-开0708 | F23: 786651400300 | G23: 0 | H23: 0 | I23: 0 | J23: 0 | K23: 356 | L23: 315 | M23: 26.65% | N23: 13 | O23: 淘天 | P23: =_xlfn.XLOOKUP(D23,TOP客户累计改善清单!E:E,TOP客户累计改善清单!K:K) -> 1 | Q23: =IF(O23="抖音",H23,L23) -> 315 | R23: =IF(O23="抖音",ROUND(I23*100,2),ROUND(M23*100,2)) -> 26.65 | S23: =C23&"・"&E23&"【"&Q23&"票"&","&R23&"%"&"】"&P23&"次" -> 河南虞城县公司李老家乡服务站・马开-开0708【315票,26.65%】1次
A24: 46222 | B24: 义乌 | C24: 浙江义乌稠江汇通路公司物流园服务部 | D24: 浙江义乌稠江汇通路公司物流园服务部菜鸟仓c2m----tb62883211322003 | E24: 菜鸟仓c2m----tb6288 | F24: 3211322003 | G24: 0 | H24: 0 | I24: 0 | J24: 0 | K24: 422 | L24: 313 | M24: 0.28% | N24: 164 | O24: 淘天 | P24: =_xlfn.XLOOKUP(D24,TOP客户累计改善清单!E:E,TOP客户累计改善清单!K:K) -> 2 | Q24: =IF(O24="抖音",H24,L24) -> 313 | R24: =IF(O24="抖音",ROUND(I24*100,2),ROUND(M24*100,2)) -> 0.28 | S24: =C24&"・"&E24&"【"&Q24&"票"&","&R24&"%"&"】"&P24&"次" -> 浙江义乌稠江汇通路公司物流园服务部・菜鸟仓c2m----tb6288【313票,0.28%】2次
A25: 46223 | B25: 苏州 | C25: 江苏常熟东南公司 | D25: 江苏常熟东南公司赵振振-郑贵清专属文艺小铺子138213416669 | E25: 赵振振-郑贵清专属文艺小铺子 | F25: 138213416669 | G25: 1810 | H25: 1573 | I25: 80.54% | J25: 52 | K25: 0 | L25: 0 | M25: 0 | N25: 0 | O25: 抖音 | P25: =_xlfn.XLOOKUP(D25,TOP客户累计改善清单!E:E,TOP客户累计改善清单!K:K) -> 2 | Q25: =IF(O25="抖音",H25,L25) -> 1573 | R25: =IF(O25="抖音",ROUND(I25*100,2),ROUND(M25*100,2)) -> 80.54 | S25: =C25&"・"&E25&"【"&Q25&"票"&","&R25&"%"&"】"&P25&"次" -> 江苏常熟东南公司・赵振振-郑贵清专属文艺小铺子【1573票,80.54%】2次
A26: 46223 | B26: 义乌 | C26: 浙江金华金东金义新区公司悦湖分部 | D26: 浙江金华金东金义新区公司悦湖分部常连杰-Pomelosee柚见417738416755 | E26: 常连杰-Pomelosee柚见 | F26: 417738416755 | G26: 1741 | H26: 1572 | I26: 17.43% | J26: 35 | K26: 0 | L26: 0 | M26: 0 | N26: 0 | O26: 抖音 | P26: =_xlfn.XLOOKUP(D26,TOP客户累计改善清单!E:E,TOP客户累计改善清单!K:K) -> 1 | Q26: =IF(O26="抖音",H26,L26) -> 1572 | R26: =IF(O26="抖音",ROUND(I26*100,2),ROUND(M26*100,2)) -> 17.43 | S26: =C26&"・"&E26&"【"&Q26&"票"&","&R26&"%"&"】"&P26&"次" -> 浙江金华金东金义新区公司悦湖分部・常连杰-Pomelosee柚见【1572票,17.43%】1次
A27: 46223 | B27: 苏州 | C27: 江苏苏州常熟市招商城公司 | D27: 江苏苏州常熟市招商城公司聚福-小灰兔681709798994 | E27: 聚福-小灰兔 | F27: 681709798994 | G27: 5333 | H27: 1176 | I27: 2.7% | J27: 217 | K27: 0 | L27: 0 | M27: 0 | N27: 0 | O27: 抖音 | P27: =_xlfn.XLOOKUP(D27,TOP客户累计改善清单!E:E,TOP客户累计改善清单!K:K) -> 1 | Q27: =IF(O27="抖音",H27,L27) -> 1176 | R27: =IF(O27="抖音",ROUND(I27*100,2),ROUND(M27*100,2)) -> 2.7 | S27: =C27&"・"&E27&"【"&Q27&"票"&","&R27&"%"&"】"&P27&"次" -> 江苏苏州常熟市招商城公司・聚福-小灰兔【1176票,2.7%】1次
A28: 46223 | B28: 湖北 | C28: 湖北鄂州华容新葛店公司 | D28: 湖北鄂州华容新葛店公司天门-石总-雅韵阁310571275551 | E28: 天门-石总-雅韵阁 | F28: 310571275551 | G28: 1223 | H28: 1108 | I28: 71.9% | J28: 315 | K28: 0 | L28: 0 | M28: 0 | N28: 0 | O28: 抖音 | P28: =_xlfn.XLOOKUP(D28,TOP客户累计改善清单!E:E,TOP客户累计改善清单!K:K) -> 1 | Q28: =IF(O28="抖音",H28,L28) -> 1108 | R28: =IF(O28="抖音",ROUND(I28*100,2),ROUND(M28*100,2)) -> 71.9 | S28: =C28&"・"&E28&"【"&Q28&"票"&","&R28&"%"&"】"&P28&"次" -> 湖北鄂州华容新葛店公司・天门-石总-雅韵阁【1108票,71.9%】1次
A29: 46223 | B29: 湖北 | C29: 湖北鄂州华容新葛店公司 | D29: 湖北鄂州华容新葛店公司天门-石总-江南女神五店310571429050 | E29: 天门-石总-江南女神五店 | F29: 310571429050 | G29: 3641 | H29: 1022 | I29: 14.56% | J29: 499 | K29: 0 | L29: 0 | M29: 0 | N29: 0 | O29: 抖音 | P29: =_xlfn.XLOOKUP(D29,TOP客户累计改善清单!E:E,TOP客户累计改善清单!K:K) -> 1 | Q29: =IF(O29="抖音",H29,L29) -> 1022 | R29: =IF(O29="抖音",ROUND(I29*100,2),ROUND(M29*100,2)) -> 14.56 | S29: =C29&"・"&E29&"【"&Q29&"票"&","&R29&"%"&"】"&P29&"次" -> 湖北鄂州华容新葛店公司・天门-石总-江南女神五店【1022票,14.56%】1次
A30: 46223 | B30: 山西 | C30: 山西阳高县公司 | D30: 山西阳高县公司山西阳高杏脯店355594302505 | E30: 山西阳高杏脯店 | F30: 355594302505 | G30: 0 | H30: 0 | I30: 0 | J30: 0 | K30: 1498 | L30: 1498 | M30: 100% | N30: 1498 | O30: 淘天 | P30: =_xlfn.XLOOKUP(D30,TOP客户累计改善清单!E:E,TOP客户累计改善清单!K:K) -> 1 | Q30: =IF(O30="抖音",H30,L30) -> 1498 | R30: =IF(O30="抖音",ROUND(I30*100,2),ROUND(M30*100,2)) -> 100 | S30: =C30&"・"&E30&"【"&Q30&"票"&","&R30&"%"&"】"&P30&"次" -> 山西阳高县公司・山西阳高杏脯店【1498票,100%】1次
A31: 46223 | B31: 河南 | C31: 河南新温县公司自营区分部 | D31: 河南新温县公司自营区分部妈妈精品店-百合DD766640565138 | E31: 妈妈精品店-百合DD | F31: 766640565138 | G31: 45 | H31: 44 | I31: 63.77% | J31: 0 | K31: 726 | L31: 726 | M31: 68.62% | N31: 19 | O31: 淘天 | P31: =_xlfn.XLOOKUP(D31,TOP客户累计改善清单!E:E,TOP客户累计改善清单!K:K) -> 1 | Q31: =IF(O31="抖音",H31,L31) -> 726 | R31: =IF(O31="抖音",ROUND(I31*100,2),ROUND(M31*100,2)) -> 68.62 | S31: =C31&"・"&E31&"【"&Q31&"票"&","&R31&"%"&"】"&P31&"次" -> 河南新温县公司自营区分部・妈妈精品店-百合DD【726票,68.62%】1次
A32: 46223 | B32: 贵州 | C32: 贵州习水县公司 | D32: 贵州习水县公司周陆军5646004933 | E32: 周陆军 | F32: 5646004933 | G32: 0 | H32: 0 | I32: 0 | J32: 0 | K32: 531 | L32: 531 | M32: 100% | N32: 0 | O32: 淘天 | P32: =_xlfn.XLOOKUP(D32,TOP客户累计改善清单!E:E,TOP客户累计改善清单!K:K) -> 3 | Q32: =IF(O32="抖音",H32,L32) -> 531 | R32: =IF(O32="抖音",ROUND(I32*100,2),ROUND(M32*100,2)) -> 100 | S32: =C32&"・"&E32&"【"&Q32&"票"&","&R32&"%"&"】"&P32&"次" -> 贵州习水县公司・周陆军【531票,100%】3次
A33: 46223 | B33: 天津 | C33: 天津宝坻区新城公司 | D33: 天津宝坻区新城公司公司自营506045559913 | E33: 公司自营 | F33: 506045559913 | G33: 0 | H33: 0 | I33: 0 | J33: 0 | K33: 494 | L33: 494 | M33: 4.99% | N33: 0 | O33: 淘天 | P33: =_xlfn.XLOOKUP(D33,TOP客户累计改善清单!E:E,TOP客户累计改善清单!K:K) -> 1 | Q33: =IF(O33="抖音",H33,L33) -> 494 | R33: =IF(O33="抖音",ROUND(I33*100,2),ROUND(M33*100,2)) -> 4.99 | S33: =C33&"・"&E33&"【"&Q33&"票"&","&R33&"%"&"】"&P33&"次" -> 天津宝坻区新城公司・公司自营【494票,4.99%】1次
A34: 46223 | B34: 南京 | C34: 江苏徐州铜山区彭城公司 | D34: 江苏徐州铜山区彭城公司乐淘淘873840521933 | E34: 乐淘淘 | F34: 873840521933 | G34: 0 | H34: 0 | I34: 0 | J34: 0 | K34: 361 | L34: 341 | M34: 2.12% | N34: 341 | O34: 淘天 | P34: =_xlfn.XLOOKUP(D34,TOP客户累计改善清单!E:E,TOP客户累计改善清单!K:K) -> 1 | Q34: =IF(O34="抖音",H34,L34) -> 341 | R34: =IF(O34="抖音",ROUND(I34*100,2),ROUND(M34*100,2)) -> 2.12 | S34: =C34&"・"&E34&"【"&Q34&"票"&","&R34&"%"&"】"&P34&"次" -> 江苏徐州铜山区彭城公司・乐淘淘【341票,2.12%】1次
A35: 46224 | B35: 苏州 | C35: 江苏苏州常熟莫城公司 | D35: 江苏苏州常熟莫城公司吴彦祖-陈浩565115100439 | E35: 吴彦祖-陈浩 | F35: 565115100439 | G35: 2211 | H35: 1825 | I35: 33.61% | J35: 281 | K35: 0 | L35: 0 | M35: 0 | N35: 0 | O35: 抖音 | P35: =_xlfn.XLOOKUP(D35,TOP客户累计改善清单!E:E,TOP客户累计改善清单!K:K) -> 3 | Q35: =IF(O35="抖音",H35,L35) -> 1825 | R35: =IF(O35="抖音",ROUND(I35*100,2),ROUND(M35*100,2)) -> 33.61 | S35: =C35&"・"&E35&"【"&Q35&"票"&","&R35&"%"&"】"&P35&"次" -> 江苏苏州常熟莫城公司・吴彦祖-陈浩【1825票,33.61%】3次
A36: 46224 | B36: 河南 | C36: 河南漯河公司召陵镇黄河路中分部 | D36: 河南漯河公司召陵镇黄河路中分部仁聚462534100020 | E36: 仁聚 | F36: 462534100020 | G36: 10630 | H36: 1292 | I36: 2.19% | J36: 41 | K36: 2325 | L36: 621 | M36: 14.1% | N36: 10 | O36: 抖音 | P36: =_xlfn.XLOOKUP(D36,TOP客户累计改善清单!E:E,TOP客户累计改善清单!K:K) -> 2 | Q36: =IF(O36="抖音",H36,L36) -> 1292 | R36: =IF(O36="抖音",ROUND(I36*100,2),ROUND(M36*100,2)) -> 2.19 | S36: =C36&"・"&E36&"【"&Q36&"票"&","&R36&"%"&"】"&P36&"次" -> 河南漯河公司召陵镇黄河路中分部・仁聚【1292票,2.19%】2次
A37: 46224 | B37: 广佛中 | C37: 广东佛山南海新河村公司 | D37: 广东佛山南海新河村公司GJ黄总新-解忧原创手机壳抖音572014996265 | E37: GJ黄总新-解忧原创手机壳抖音 | F37: 572014996265 | G37: 1803 | H37: 1228 | I37: 8.64% | J37: 684 | K37: 0 | L37: 0 | M37: 0 | N37: 0 | O37: 抖音 | P37: =_xlfn.XLOOKUP(D37,TOP客户累计改善清单!E:E,TOP客户累计改善清单!K:K) -> 3 | Q37: =IF(O37="抖音",H37,L37) -> 1228 | R37: =IF(O37="抖音",ROUND(I37*100,2),ROUND(M37*100,2)) -> 8.64 | S37: =C37&"・"&E37&"【"&Q37&"票"&","&R37&"%"&"】"&P37&"次" -> 广东佛山南海新河村公司・GJ黄总新-解忧原创手机壳抖音【1228票,8.64%】3次
A38: 46224 | B38: 深莞惠 | C38: 广东东莞厚街公司 | D38: 广东东莞厚街公司智诚个体店-KH潘总160359819201 | E38: 智诚个体店-KH潘总 | F38: 160359819201 | G38: 2663 | H38: 1226 | I38: 46.02% | J38: 0 | K38: 0 | L38: 0 | M38: 0 | N38: 0 | O38: 抖音 | P38: =_xlfn.XLOOKUP(D38,TOP客户累计改善清单!E:E,TOP客户累计改善清单!K:K) -> 1 | Q38: =IF(O38="抖音",H38,L38) -> 1226 | R38: =IF(O38="抖音",ROUND(I38*100,2),ROUND(M38*100,2)) -> 46.02 | S38: =C38&"・"&E38&"【"&Q38&"票"&","&R38&"%"&"】"&P38&"次" -> 广东东莞厚街公司・智诚个体店-KH潘总【1226票,46.02%】1次
A39: 46224 | B39: 义乌 | C39: 浙江义乌金义都市新区公司菜鸟园分部 | D39: 浙江义乌金义都市新区公司菜鸟园分部常连杰-邱须良品奢企业店896519745234 | E39: 常连杰-邱须良品奢企业店 | F39: 896519745234 | G39: 1471 | H39: 1086 | I39: 11.06% | J39: 21 | K39: 0 | L39: 0 | M39: 0 | N39: 0 | O39: 抖音 | P39: =_xlfn.XLOOKUP(D39,TOP客户累计改善清单!E:E,TOP客户累计改善清单!K:K) -> 1 | Q39: =IF(O39="抖音",H39,L39) -> 1086 | R39: =IF(O39="抖音",ROUND(I39*100,2),ROUND(M39*100,2)) -> 11.06 | S39: =C39&"・"&E39&"【"&Q39&"票"&","&R39&"%"&"】"&P39&"次" -> 浙江义乌金义都市新区公司菜鸟园分部・常连杰-邱须良品奢企业店【1086票,11.06%】1次
A40: 46224 | B40: 河南 | C40: 河南漯河公司召陵镇黄河路中分部 | D40: 河南漯河公司召陵镇黄河路中分部仁聚462534100020 | E40: 仁聚 | F40: 462534100020 | G40: 10630 | H40: 1292 | I40: 2.19% | J40: 41 | K40: 2325 | L40: 621 | M40: 14.1% | N40: 10 | O40: 淘天 | P40: =_xlfn.XLOOKUP(D40,TOP客户累计改善清单!E:E,TOP客户累计改善清单!K:K) -> 2 | Q40: =IF(O40="抖音",H40,L40) -> 621 | R40: =IF(O40="抖音",ROUND(I40*100,2),ROUND(M40*100,2)) -> 14.1 | S40: =C40&"・"&E40&"【"&Q40&"票"&","&R40&"%"&"】"&P40&"次" -> 河南漯河公司召陵镇黄河路中分部・仁聚【621票,14.1%】2次
...

Sheet Sheet2
J15: 发保健品、百货，日均20000单，活动爆单，销量翻倍，缺货，打包动力不足 | K15: 加急备货 加派人手打包
J17: 客户缺货，提前揽收导致 | K17: 网点做始发退回闭环
J19: 发保健品、百货，日均20000单，活动爆单，销量翻倍，缺货，打包动力不足 | K19: 加急备货 加派人手打包
J21: 商家无货提前打单 | K21: 已让网点和客户沟通停止提前打单
J23: 客户缺货 | K23: 缺货商品停止揽收挂预售

Sheet 上榜过且清退过的网点
A1: 一级 | B1: 最近一天限制取号 | C1: 上榜次数 | D1: 清退次数 | H1: 网点名称 | I1: 上级公司名称
A2: 河南商丘睢阳神火公司 | B2: 46209 | C2: 8 | D2: 5 | H2: 北京朝阳区亚运村公司 | I2: 北京朝阳区亚运村公司
A3: 河北韵达鑫通公司 | B3: 46209 | C3: 38 | D3: 3 | H3: 北京昌平区昌平公司 | I3: 北京昌平区昌平公司
A4: 广东深圳公司 | B4: 46198 | C4: 1 | D4: 3 | H4: 北京丰台区腾飞公司 | I4: 北京丰台区腾飞公司
A5: 广东广州天河区渔沙坦公司 | B5: 46196 | C5: 29 | D5: 1 | H5: 北京怀柔区公司 | I5: 北京怀柔区公司
A6: 福建漳州龙海区高新公司 | B6: 46128 | C6: 4 | D6: 1 | H6: 北京密云区公司 | I6: 北京密云区公司
A7: 广东深圳KH公司 | B7: 46109 | C7: 15 | D7: 3 | H7: 北京延庆区公司 | I7: 北京延庆区公司
A8: 湖北天门市公司 | B8: 46100 | C8: 19 | D8: 4 | H8: 北京大兴区龙腾公司 | I8: 北京大兴区龙腾公司
A9: 江西南昌红谷滩新区昌北公司 | B9: 46087 | C9: 3 | D9: 1 | H9: 北京平谷区公司 | I9: 北京平谷区公司
A10: 广东中山富民公司 | B10: 46087 | C10: 1 | D10: 3 | H10: 北京海淀区万寿路公司 | I10: 北京海淀区万寿路公司
A11: 广东广州番禺南村公司 | B11: 46087 | C11: 4 | D11: 3 | H11: 北京西城区百万庄公司 | I11: 北京西城区百万庄公司
A12: 浙江义乌廿三里公司 | B12: 46087 | C12: 8 | D12: 2 | H12: 北京海淀区上地公司 | I12: 北京海淀区上地公司
A13: 浙江金华金东金义新区公司 | B13: 46087 | C13: 4 | D13: 1 | H13: 北京海淀区中关村西北区公司 | I13: 北京海淀区中关村西北区公司
... A47: 河北南宫市公司 | B47: 45207 | C47: 1 | D47: 1 | H47: 北京海淀区安宁庄公司 | I47: 北京海淀区安宁庄公司
H48: 北京丰台区蒲黄榆公司 | I48: 北京丰台区蒲黄榆公司
H49: 华北韵达金韵公司 | I49: 华北韵达金韵公司
H50: 北京朝阳区远洋公司 | I50: 北京朝阳区远洋公司
H51: 北京大兴区工业区公司 | I51: 北京大兴区工业区公司
H52: 北京韵达金韵公司朝阳区伊藤忠分部 | I52: 华北韵达金韵公司
H53: 北京丰台区丰体公司 | I53: 北京丰台区丰体公司
H54: 北京丰台区丰北路公司 | I54: 北京丰台区丰北路公司
H55: 北京大兴区西红门公司 | I55: 北京大兴区西红门公司
H56: 北京丰台区飞宇公司 | I56: 北京丰台区飞宇公司
H57: 北京朝阳区新方庄公司 | I57: 北京朝阳区新方庄公司
H58: 北京朝阳区大营公司 | I58: 北京朝阳区大营公司
H59: 北京朝阳区官庄公司 | I59: 北京朝阳区官庄公司
... H24161: 辽宁沈阳铁西鸿运顺达公司兴华西分部 | I24161: 辽宁沈阳铁西鸿运顺达公司

Sheet Sheet1
A1: 上榜日期 | B1: 省 | C1: 分部名称 | D1: 唯一值（分部名称+客户名称+客户编码 | E1: 客户名称 | F1: 客户编码 | G1: 超时原因 | H1: 整改动作 | I1: 达成日期
A2: 46168 | B2: 深莞惠 | C2: 广东东莞中堂公司文豪分部 | D2: 广东东莞中堂公司文豪分部诺诺潮流服饰抖音-6045370521112998 | E2: 诺诺潮流服饰抖音-6045 | F2: 370521112998 | G2: 客户主售服装类，缺货导致 | H2: 网点已联系客户沟通，三天内整改，客户无改善停止合作 | I2: 46171
A3: 46168 | B3: 江西 | C3: 江西南昌新建区九龙湖公司西客站服务部 | D3: 江西南昌新建区九龙湖公司西客站服务部刘小霞102943623943 | E3: 刘小霞 | F3: 102943623943 | G3: 1.新做的云仓客户，刚搬进来，产品日用品，目前发货1.5万票左右，产品库存不足 | H3: 1.客户缺货要求网点做预售，禁止提前揽收 | I3: 46171
A4: 46168 | B4: 揭阳 | C4: 广东汕头龙湖澄海外砂公司 | D4: 广东汕头龙湖澄海外砂公司(1043海)颂伊-宝趣玩具18d515768570578 | E4: (1043海)颂伊-宝趣玩具18d | F4: 515768570578 | G4: 1.客户突然爆单，部分商品缺货，打包人手不足，导致揽交超时。 | H4: 1.已经通知商家增加人手打包，和厂家对接好，确保货源 。 2.客户缺货的情况下设置预售，禁止提前揽收。 | I4: 46173
A5: 46168 | B5: 新疆 | C5: 新疆和田市公司昆玉分部 | D5: 新疆和田市公司昆玉分部公司策勒客户拓十三零食旗舰店990710300048 | E5: 公司策勒客户拓十三零食旗舰店 | F5: 990710300048 | G5: 距离网点1200公里在途实际需要26个小时，72-96小时特殊考核 | I5: -
A6: 46168 | B6: 广佛中 | C6: 广东广州番禺南村公司朝阳服务部 | D6: 广东广州番禺南村公司朝阳服务部帛卡-法蒙-LaChapelleLC官方旗舰店-天猫抖音695421957175 | E6: 帛卡-法蒙-LaChapelleLC官方旗舰店-天猫抖音 | F6: 695421957175 | G6: 客户爆单缺货 | H6: 始发退回 | I6: 46176
A7: 46168 | B7: 广佛中 | C7: 广东广州白云区大源公司鑫都服务部 | D7: 广东广州白云区大源公司鑫都服务部158133dan-熠宸云仓(2238-小柴)418388101050 | E7: 158133dan-熠宸云仓(2238-小柴) | F7: 418388101050 | G7: 客户爆单缺货 | H7: 始发提回 | I7: 46176
A8: 46168 | B8: 湖北 | C8: 湖北武汉东西湖走马岭公司优选分部 | D8: 湖北武汉东西湖走马岭公司优选分部恒大-大米767872317891 | E8: 恒大-大米 | F8: 767872317891 | G8: 大部分为网点直发未经过分拨 | H8: 未直发发运超时快件联系网点及时对接客户催交 | I8: 46172
A9: 46168 | B9: 四川 | C9: 四川成都金牛五块石公司 | D9: 四川成都金牛五块石公司四川佰河供应链有限公司611534188888 | E9: 四川佰河供应链有限公司 | F9: 611534188888 | G9: 同省礼品件，商家无货做了虚假揽收导致发运超时 | H9: 已经警告商家无货不要做揽收，再次发现关闭该商家的一件揽收功能 | I9: 46172
A10: 46168 | B10: 江西 | C10: 江西南昌青山湖罗家集公司东泰大道服务部 | D10: 江西南昌青山湖罗家集公司东泰大道服务部牛心飞2655031070 | E10: 牛心飞 | F10: 2655031070 | G10: 客户打单后取消订单、内网无任何记录、因配置完美物流导致超时（网点反映取消了完美物流、自动打开了） | H10: 1.已要求网点申请重新取消完美物流配置 2.确定当日取消订单快件、及时做始发退回完结时效 | I10: 46171
A11: 46167 | B11: 揭阳 | C11: 广东汕头龙湖澄海外砂公司 | D11: 广东汕头龙湖澄海外砂公司(1043海)颂伊-宝趣玩具18d515768570578 | E11: (1043海)颂伊-宝趣玩具18d | F11: 515768570578 | G11: 客户打包人手不足，前段时间调整有增加临时工，近期临时工不稳定导致打包人手不足。 | H11: 目前客户找了几家小时工外包公司，先撑过这段时间，客户已经陆续，在招一部分自有的员工。 | I11: 46173
A12: 46167 | B12: 河北 | C12: 河北南宫市公司南宫服务部 | D12: 河北南宫市公司南宫服务部紫冢惠-田冬芳-抖音惠洋夫人围巾-淘宝美夫人围巾-拼多多惠洋夫人围巾-视频号惠熙熙衣帽屋795303500071 | E12: 紫冢惠-田冬芳-抖音惠洋夫人围巾-淘宝美夫人围巾-拼多多惠洋夫人围巾-视频号惠熙熙衣帽屋 | F12: 795303500071 | G12: 客户爆单缺货 | H12: 目前已恢复正常 | I12: 46173
A13: 46167 | B13: 湖北 | C13: 湖北孝感新孝南公司美宜佳分部 | D13: 湖北孝感新孝南公司美宜佳分部TM涛哥-张泼(抖音)787122100594 | E13: TM涛哥-张泼(抖音) | F13: 787122100594 | G13: 客户缺货 | H13: 已联系网点后续无改善，总部驳回完美物流申请 | I13: 46170
A14: 46167 | B14: 广佛中 | C14: 广东广州花都区新雅公司天闽汇服务部 | D14: 广东广州花都区新雅公司天闽汇服务部P03-平价高质-抖音-巫总-杨小芳354001681119 | E14: P03-平价高质-抖音-巫总-杨小芳 | F14: 354001681119 | G14: 缺货 | H14: 网点做始发退回 | I14: 46175
A15: 46167 | B15: 深莞惠 | C15: 广东东莞中堂公司文豪分部 | D15: 广东东莞中堂公司文豪分部诺诺潮流服饰抖音-6045370521112998 | E15: 诺诺潮流服饰抖音-6045 | F15: 370521112998 | G15: 客户主售服装类，缺货导致 | H15: 网点已联系客户沟通，三天内整改，客户无改善停止合作 | I15: 46171
A16: 46167 | B16: 山西 | C16: 山西汾阳市公司 | D16: 山西汾阳市公司玩偶932200472252 | E16: 玩偶 | F16: 932200472252 | G16: 同城件订单未及时签收 | H16: 已通知网点同城件订单揽收后及时签收 | I16: 46170
A17: 46167 | B17: 南京 | C17: 江苏南京浦口区新城公司 | D17: 江苏南京浦口区新城公司凤凰新华书店211149548426 | E17: 凤凰新华书店 | F17: 211149548426 | G17: 客户存在打单后取消订单行为，商家现场扫描直接拦截带回，导致内网无扫描记录，且配置完美物流导致发运超时 | H17: 已通知网点沟通客户，针对发运超时做考核，且关闭完美物流 | I17: 46170
... A28: 46166 | B28: 南京 | C28: 江苏南京浦口区新城公司 | D28: 江苏南京浦口区新城公司凤凰新华书店211149548426 | E28: 凤凰新华书店 | F28: 211149548426 | G28: 客户存在打单后取消订单行为，商家现场扫描直接拦截带回，导致内网无扫描记录，且配置完美物流导致发运超时 | H28: 已通知网点沟通客户，针对发运超时做考核，且关闭完美物流 | I28: 46173
A29: 46166 | B29: 湖北 | C29: 湖北孝感新孝南公司美宜佳分部 | D29: 湖北孝感新孝南公司美宜佳分部YC张庆(顺贤供应链)(淘宝)787122100065 | E29: YC张庆(顺贤供应链)(淘宝) | F29: 787122100065 | G29: 网点直发车未经过分拨 | H29: - | I29: -
A30: 46166 | B30: 河北 | C30: 河北石家庄赞皇县公司 | D30: 河北石家庄赞皇县公司门市下单95005493213 | E30: 门市下单 | F30: 95005493213 | G30: 商家缺货 | H30: 已通知网点负责人跟进客户交货情况 | I30: 46174
A31: 46165 | B31: 广佛中 | C31: 广东佛山南海新河村公司 | D31: 广东佛山南海新河村公司曼馨-业彬护肤专营店328起拉均-臻颜视频号667400325337 | E31: 曼馨-业彬护肤专营店328起拉均-臻颜视频号 | F31: 667400325337 | G31: 美妆客户日均8万票，活动期间13万票，发韵达3万票，平常缺货5%左右，22号客户的供应商生产线故障，23号才将货品给到客户这边打包，导致揽件未交大幅度上涨 | H31: 今天已经恢复正常，已跟客户沟通好后续这种突发状况及时反馈给网点，总部也已同步开通分拨兜底规避物流轨迹超时考核 | I31: 46167
A32: 46165 | B32: 揭阳 | C32: 广东汕头龙湖澄海外砂公司 | D32: 广东汕头龙湖澄海外砂公司(1043海)颂伊-宝趣玩具18d515768570578 | E32: (1043海)颂伊-宝趣玩具18d | F32: 515768570578 | G32: 客户打包人手不足，前段时间调整有增加临时工，近期临时工不稳定导致打包人手不足。 | H32: 目前客户找了几家小时工外包公司，先撑过这段时间，客户已经陆续，在招一部分自有的员工。 | I32: 46203
A33: 46165 | B33: 新疆 | C33: 新疆和田市公司昆玉分部 | D33: 新疆和田市公司昆玉分部公司策勒客户拓十三零食旗舰店990710300048 | E33: 公司策勒客户拓十三零食旗舰店 | F33: 990710300048 | G33: 距离网点1200公里在途实际需要26个小时，72-96小时特殊考核 | I33: -
A34: 46165 | B34: 广佛中 | C34: 广东广州花都区新雅公司镜湖分部 | D34: 广东广州花都区新雅公司镜湖分部P93-古桃女装-抖音-赵总961132100009 | E34: P93-古桃女装-抖音-赵总 | F34: 961132100009 | G34: 服装客户，日均5000票，缺货 | H34: 已开通自动始发退回兜底 | I34: 46168
A35: 46165 | B35: 湖北 | C35: 湖北武汉东西湖走马岭公司优选分部 | D35: 湖北武汉东西湖走马岭公司优选分部兴永商贸767872610012 | E35: 兴永商贸 | F35: 767872610012 | G35: 走马岭直发未经过分拨
A36: 46165 | B36: 内蒙 | C36: 内蒙古察右后旗公司 | D36: 内蒙古察右后旗公司陈少东912846891519 | E36: 陈少东 | F36: 912846891519 | G36: 库房新人提前打单 | H36: 对新人做培训、交不出来的做始发退回 | I36: 46167
A37: 46165 | B37: 天津 | C37: 天津武清区大王古公司大王古寄存点 | D37: 天津武清区大王古公司大王古寄存点河务竹卜湿巾通用账号762280888812 | E37: 河务竹卜湿巾通用账号 | F37: 762280888812 | G37: 客户缺货，提前揽收 | H37: 已和网点负责人沟通，续不再出现此类情况 | I37: -
A38: 46165 | B38: 福建 | C38: 福建涵东公司 | D38: 福建涵东公司zys20089459974517716 | E38: zys20089 | F38: 459974517716 | G38: 服装类客户，无库存，需要工厂生产 | H38: 要求客户缺货不打单，网点不提前揽收 | I38: 46174
A39: 46165 | B39: 深莞惠 | C39: 广东深圳KH公司天地通电讯分部 | D39: 广东深圳KH公司天地通电讯分部lianxinglei518537296547 | E39: lianxinglei | F39: 518537296547 | G39: 客户是因为深圳暴雨影响，交货到集包仓在5.30后，导致滞留延误 | H39: 今天已恢复正常 | I39: 46167
A40: 46165 | B40: 四川 | C40: 四川成都双流KH公司龙潭寺服务部 | D40: 四川成都双流KH公司龙潭寺服务部沧海墙纸729857445555 | E40: 沧海墙纸 | F40: 729857445555 | G40: 初次操作集包，流程不熟悉，设备调试并且新建网格仓离乐至分拨较远；网格仓新上岗司机路途不熟 | H40: 通知集包仓加快设备维护进度和使用熟练度，培养司机熟悉揽货交货位置； | I40: 46170
A41: 46163 | B41: 广西 | C41: 广西南宁江南公司新城服务部 | D41: 广西南宁江南公司新城服务部皆用水果-李庆锋抖音568514800102 | E41: 皆用水果-李庆锋抖音 | F41: 568514800102 | G41: 客户水果质量不好，挑好的发部分未能发出待补货； | H41: 已通知网点负责人跟进客户不要提前打单； | I41: 46167
A42: 46163 | B42: 义乌 | C42: 浙江义乌和兴公司 | D42: 浙江义乌和兴公司公司A-康言生活a帷昕甄选322003726594 | E42: 公司A-康言生活a帷昕甄选 | F42: 322003726594 | G42: 这个客户是卖这个产品的 因为现在这个产品是旺季 厂家生产部过来 发来的都是没组装的 客户打包的时候 需要组装 还要数片数 打包就很慢 导致部分货物当天发不完 | H42: 1，客户增加打包人手 2， 客户现在也在重新找生产组装好的厂家 | I42: 46167
A43: 46163 | B43: 揭阳 | C43: 广东汕头龙湖澄海外砂公司 | D43: 广东汕头龙湖澄海外砂公司(1043海)颂伊-宝趣玩具18d515768570578 | E43: (1043海)颂伊-宝趣玩具18d | F43: 515768570578 | G43: 1.客户突然爆单，部分商品缺货，打包人手不足，导致揽交超时。 | H43: 1.已经通知商家增加人手打包，和厂家对接好，确保货源 。 2.客户缺货的情况下设置预售，禁止提前揽收。 | I43: 46170
A44: 46163 | B44: 广西 | C44: 广西南宁青秀区凤岭公司崇铭服务部 | D44: 广西南宁青秀区凤岭公司崇铭服务部300011淘宝我xxxxxxi京东KSLJD003拼多多馋馋鲜果蔬抖音新红薯基地快手an秀白马视频号馋鲜旺客来313059300011 | E44: 300011淘宝我xxxxxxi京东KSLJD003拼多多馋馋鲜果蔬抖音新红薯基地快手an秀白马视频号馋鲜旺客来 | F44: 313059300011 | G44: 客户已打单缺货未发 | H44: 已通知网点负责人跟进客户不要提前打单； | I44: 46167
A45: 46163 | B45: 青海 | C45: 青海玉树州玉树市公司 | D45: 青海玉树州玉树市公司扎家的小店铺抖音686268111116 | E45: 扎家的小店铺抖音 | F45: 686268111116 | G45: 新对接客户，业务员揽收发运一起操作掉了，业务员操作失误导致超时 | H45: 网点老板已培训业务员 | I45: 46167
A46: 46163 | B46: 河北 | C46: 河北清河县公司 | D46: 河北清河县公司陈彬彬-裴志林-822790954008837682 | E46: 陈彬彬-裴志林-822790 | F46: 954008837682 | G46: 客户缺货 | H46: 已通知网点跟进发货，如未改善关停打单权限 | I46: 46167
A47: 46163 | B47: 广西 | C47: 广西南宁青秀区凤岭公司崇铭服务部 | D47: 广西南宁青秀区凤岭公司崇铭服务部芒果16淘宝txxxxxx3拼多多小胖墩鲜鲜果京东Zz13877623868抖音小胖墩鲜鲜果快手快手用户1745932604491白马视频号星辰海精选优品3130596016 | E47: 芒果16淘宝txxxxxx3拼多多小胖墩鲜鲜果京东Zz13877623868抖音小胖墩鲜鲜果快手快手用户1745932604491白马视频号星辰海精选优品 | F47: 3130596016 | G47: 客户已打单缺货未发 | H47: 已通知网点负责人跟进客户不要提前打单； | I47: 46167
A48: 46163 | B48: 河北 | C48: 河北清河县公司清河分部 | D48: 河北清河县公司清河分部然润甄选店-刘阳-822790211444687597 | E48: 然润甄选店-刘阳-822790 | F48: 211444687597 | G48: 客户缺货 | H48: 已通知网点跟进发货，如未改善关停打单权限 | I48: 46167
A49: 46163 | B49: 湖北 | C49: 湖北武汉东西湖走马岭公司优选分部 | D49: 湖北武汉东西湖走马岭公司优选分部天门武汉鞋迷767872910017 | E49: 天门武汉鞋迷 | F49: 767872910017 | G49: 客户缺货 | H49: 已联系网点后续无改善，总部驳回完美物流申请 | I49: 46167
... A56: 46162 | B56: 福建 | C56: 福建涵东公司 | D56: 福建涵东公司ruostyle459974517714 | E56: ruostyle | F56: 459974517714 | G56: 特殊A货市场不屯货，客户缺货，需要生产，同时因反内卷涨价后客户部分件量流失至同行，缺货占比较大; | H56: 网点已安排市场部现场驻点。督促客户及时打包，缺货不打单，打单不提前揽收 | I56: 46165
...
